Workbook

Sheet Expenses  Page 1
A1: Please select language / Bitte Sprache wählen | G1: English
A4: =IF($G$1="Deutsch",Codes!$A37,Codes!$B37) -> BILL OF EXPENSES - FIXED ALLOWANCES
A6: =IF($G$1="Deutsch",Codes!$A38,Codes!$B38) -> Documentnr.
A7: =IF($G$1="Deutsch",Codes!$A40,Codes!$B40) -> First name | C7: Zenabu | H7: =IF($G$1="Deutsch",Codes!$A47,Codes!$B47) -> Valuta (dd.mm.yyyy) | I7: 45980
A8: =IF($G$1="Deutsch",Codes!$A39,Codes!$B39) -> Last name | C8: Suboi | H8: =IF($G$1="Deutsch",Codes!$A88,Codes!$B88) -> Finalised by
A9: =IF($G$1="Deutsch",Codes!$A41,Codes!$B41) -> Address | C9: HBC, BOX 12914, CHANTAN - LAPAZ
A10: =IF($G$1="Deutsch",Codes!$A42,Codes!$B42) -> ZIP/Place | C10: ACCRA - GHANA
A11: =IF($G$1="Deutsch",Codes!$A43,Codes!$B43) -> Mission/Purpose | C11: To attend ASTMH 2025 Annual Meeting
A12: =IF($G$1="Deutsch",Codes!$A44,Codes!$B44) -> Cost centre | C12: 4545 | F12: =IF($G$1="Deutsch",Codes!$A48,Codes!$B48) -> Currency (for payment) | G12: USD
A13: =IF($G$1="Deutsch",Codes!$A45,Codes!$B45) -> From (date) | C13: 45970 | F13: =IF($G$1="Deutsch",Codes!$A49,Codes!$B49) -> To (date) | G13: 45974
A14: =IF($G$1="Deutsch",Codes!$A46,Codes!$B46) -> Place | C14: Toronto | F14: =IF($G$1="Deutsch",Codes!$A50,Codes!$B50) -> Country | G14: Canada
A16: =IF($G$1="Deutsch",Codes!$A51,Codes!$B51) -> FIXED ALLOWANCES | D16: JA | E16: =IF($G$1="Deutsch",Codes!$A52,Codes!$B52) -> Applicable (please select YES or NO)
A17: =IF($G$1="Deutsch",Codes!$A53,Codes!$B53) -> Lump sum per day
A18: =IF($G$1="Deutsch",Codes!$A54,Codes!$B54) -> Disbursement | B18: =IF($G$1="Deutsch",Codes!$A54,Codes!$B54) -> Disbursement | C18: =IF($G$1="Deutsch",Codes!$A54,Codes!$B54) -> Disbursement | D18: =IF($G$1="Deutsch",Codes!$A54,Codes!$B54) -> Disbursement | E18: =IF($G$1="Deutsch",Codes!$A54,Codes!$B54) -> Disbursement | F18: =IF($G$1="Deutsch",Codes!$A55,Codes!$B55) -> Quantity | G18: =IF($G$1="Deutsch",Codes!$A56,Codes!$B56) -> Budget line | H18: =IF($G$1="Deutsch",Codes!$A57,Codes!$B57) -> Amount | I18: =IF($G$1="Deutsch",Codes!$A58,Codes!$B58) -> Amount CHF
A19: =IF($G$1="Deutsch",Codes!$A59,Codes!$B59) -> Breakfast | B19: =IF($G$1="Deutsch",Codes!$A55,Codes!$B55) -> Quantity | C19: =IF($G$1="Deutsch",Codes!$A62,Codes!$B62) -> If departures is before 7.30 am or respectively with overnight stay (only in case breakfast is not included) | H19: 10 | I19: =IF(D$16="NO",0,IF(D$16="NEIN",0,+F19*H19)) -> 0
A20: =IF($G$1="Deutsch",Codes!$A60,Codes!$B60) -> Lunch | B20: =IF($G$1="Deutsch",Codes!$A56,Codes!$B56) -> Budget line | H20: 25 | I20: =IF(D$16="NO",0,IF(D$16="NEIN",0,+F20*H20)) -> 0
A21: =IF($G$1="Deutsch",Codes!$A61,Codes!$B61) -> Dinner | B21: =IF($G$1="Deutsch",Codes!$A57,Codes!$B57) -> Amount | C21: =IF($G$1="Deutsch",Codes!$A63,Codes!$B63) -> In case of external overnight stay or return after 7.30 pm | H21: 25 | I21: =IF(D$16="NO",0,IF(D$16="NEIN",0,+F21*H21)) -> 0
A22: =IF($G$1="Deutsch",Codes!$A64,Codes!$B64) -> Private petty expenses for mission abroad | H22: 5 | I22: =IF(D$16="NO",0,IF(D$16="NEIN",0,+F22*H22)) -> 0
A23: =IF($G$1="Deutsch",Codes!$A65,Codes!$B65) -> TOTAL FIXED ALLOWANCES | I23: =SUM(I19:I22) -> 0
F24: =IF($G$1="Deutsch",Codes!$A66,Codes!$B66) -> Exchange rate (filled in by Accounting) | G24: =IF(G12="CHF",1," ") | H24: =+G12 -> USD | I24: =IF(G12="CHF",I23," ")
A26: =IF($G$1="Deutsch",Codes!$A67,Codes!$B67) -> EXPENSES
A27: =IF($G$1="Deutsch",Codes!$A68,Codes!$B68) -> No | B27: =IF($G$1="Deutsch",Codes!$A69,Codes!$B69) -> Date | C27: =IF($G$1="Deutsch",Codes!$A70,Codes!$B70) -> Disbursement | D27: =IF($G$1="Deutsch",Codes!$A71,Codes!$B71) -> Acc.code | E27: =IF($G$1="Deutsch",Codes!$A56,Codes!$B56) -> Budget line | F27: =IF($G$1="Deutsch",Codes!$A72,Codes!$B72) -> Currency | G27: =IF($G$1="Deutsch",Codes!$A73,Codes!$B73) -> Amount | H27: =IF($G$1="Deutsch",Codes!$A74,Codes!$B74) -> Rate | I27: =IF($G$1="Deutsch",CONCATENATE(Codes!$A75," ",G$12),CONCATENATE(Codes!$B75," ",G$12)) -> Amount USD | K27: =IF($G$1="Deutsch",Codes!$A76,Codes!$B76) -> Account
A28: 1 | B28: 45936 | C28: Visa application and biometric fees | D28: =IF(ISNA(VLOOKUP(K28,Codes!A$3:B$19,2,FALSE))=TRUE,0,VLOOKUP(K28,Codes!A$3:B$19,2,FALSE)) -> 550080 | F28: CAD | G28: 185 | H28: =IF(F28=$H$24,1,0) -> 0 | I28: =IF(H28<>0,INT(20*(+G28*H28)+0.5)/20,0) -> 0 | K28: 550080 Authorizations, Fees
A29: 2 | D29: =IF(ISNA(VLOOKUP(K29,Codes!A$3:B$19,2,FALSE))=TRUE,0,VLOOKUP(K29,Codes!A$3:B$19,2,FALSE)) -> 0 | H29: =IF(F29=$H$24,1,0) -> 0 | I29: =IF(H29<>0,INT(20*(+G29*H29)+0.5)/20,0) -> 0
A30: 3 | D30: =IF(ISNA(VLOOKUP(K30,Codes!A$3:B$19,2,FALSE))=TRUE,0,VLOOKUP(K30,Codes!A$3:B$19,2,FALSE)) -> 0 | H30: =IF(F30=$H$24,1,0) -> 0 | I30: =IF(H30<>0,INT(20*(+G30*H30)+0.5)/20,0) -> 0
A31: 4 | D31: =IF(ISNA(VLOOKUP(K31,Codes!A$3:B$19,2,FALSE))=TRUE,0,VLOOKUP(K31,Codes!A$3:B$19,2,FALSE)) -> 0 | H31: =IF(F31=$H$24,1,0) -> 0 | I31: =IF(H31<>0,INT(20*(+G31*H31)+0.5)/20,0) -> 0
A32: 5 | D32: =IF(ISNA(VLOOKUP(K32,Codes!A$3:B$19,2,FALSE))=TRUE,0,VLOOKUP(K32,Codes!A$3:B$19,2,FALSE)) -> 0 | H32: =IF(F32=$H$24,1,0) -> 0 | I32: =IF(H32<>0,INT(20*(+G32*H32)+0.5)/20,0) -> 0
A33: 6 | D33: =IF(ISNA(VLOOKUP(K33,Codes!A$3:B$19,2,FALSE))=TRUE,0,VLOOKUP(K33,Codes!A$3:B$19,2,FALSE)) -> 0 | H33: =IF(F33=$H$24,1,0) -> 0 | I33: =IF(H33<>0,INT(20*(+G33*H33)+0.5)/20,0) -> 0
A34: 7 | D34: =IF(ISNA(VLOOKUP(K34,Codes!A$3:B$19,2,FALSE))=TRUE,0,VLOOKUP(K34,Codes!A$3:B$19,2,FALSE)) -> 0 | H34: =IF(F34=$H$24,1,0) -> 0 | I34: =IF(H34<>0,INT(20*(+G34*H34)+0.5)/20,0) -> 0
A35: 8 | D35: =IF(ISNA(VLOOKUP(K35,Codes!A$3:B$19,2,FALSE))=TRUE,0,VLOOKUP(K35,Codes!A$3:B$19,2,FALSE)) -> 0 | H35: =IF(F35=$H$24,1,0) -> 0 | I35: =IF(H35<>0,INT(20*(+G35*H35)+0.5)/20,0) -> 0
A36: 9 | D36: =IF(ISNA(VLOOKUP(K36,Codes!A$3:B$19,2,FALSE))=TRUE,0,VLOOKUP(K36,Codes!A$3:B$19,2,FALSE)) -> 0 | H36: =IF(F36=$H$24,1,0) -> 0 | I36: =IF(H36<>0,INT(20*(+G36*H36)+0.5)/20,0) -> 0
A37: 10 | D37: =IF(ISNA(VLOOKUP(K37,Codes!A$3:B$19,2,FALSE))=TRUE,0,VLOOKUP(K37,Codes!A$3:B$19,2,FALSE)) -> 0 | H37: =IF(F37=$H$24,1,0) -> 0 | I37: =IF(H37<>0,INT(20*(+G37*H37)+0.5)/20,0) -> 0
A38: 11 | D38: =IF(ISNA(VLOOKUP(K38,Codes!A$3:B$19,2,FALSE))=TRUE,0,VLOOKUP(K38,Codes!A$3:B$19,2,FALSE)) -> 0 | H38: =IF(F38=$H$24,1,0) -> 0 | I38: =IF(H38<>0,INT(20*(+G38*H38)+0.5)/20,0) -> 0
A39: 12 | D39: =IF(ISNA(VLOOKUP(K39,Codes!A$3:B$19,2,FALSE))=TRUE,0,VLOOKUP(K39,Codes!A$3:B$19,2,FALSE)) -> 0 | H39: =IF(F39=$H$24,1,0) -> 0 | I39: =IF(H39<>0,INT(20*(+G39*H39)+0.5)/20,0) -> 0
A40: 13 | D40: =IF(ISNA(VLOOKUP(K40,Codes!A$3:B$19,2,FALSE))=TRUE,0,VLOOKUP(K40,Codes!A$3:B$19,2,FALSE)) -> 0 | H40: =IF(F40=$H$24,1,0) -> 0 | I40: =IF(H40<>0,INT(20*(+G40*H40)+0.5)/20,0) -> 0
A41: 14 | D41: =IF(ISNA(VLOOKUP(K41,Codes!A$3:B$19,2,FALSE))=TRUE,0,VLOOKUP(K41,Codes!A$3:B$19,2,FALSE)) -> 0 | H41: =IF(F41=$H$24,1,0) -> 0 | I41: =IF(H41<>0,INT(20*(+G41*H41)+0.5)/20,0) -> 0
A43: =IF($G$1="Deutsch",Codes!$A77,Codes!$B77) -> Total Expenses Page 1 | I43: =SUM(I28:I41) -> 0
A44: =IF($G$1="Deutsch",Codes!$A78,Codes!$B78) -> Total Expenses Page 2 | I44: =+'Expenses Page 2'!I48 -> 0
A45: =IF($G$1="Deutsch",Codes!$A79,Codes!$B79) -> TOTAL EXPENSES | I45: =SUM(I43:I44) -> 0
A46: =IF($G$1="Deutsch",Codes!$A65,Codes!$B65) -> TOTAL FIXED ALLOWANCES | I46: =IF(G12<>"CHF"," ",+I23)
...

Sheet Expenses Page 2
A1: =+'Expenses Page 1'!A4 -> BILL OF EXPENSES - FIXED ALLOWANCES
A2: =IF('Expenses Page 1'!G1="Deutsch",Codes!$A91,Codes!$B91) -> Page 2
A4: =+'Expenses Page 1'!A6 -> Documentnr. | C4: =+'Expenses Page 1'!C6:I6 -> 0
A5: =+'Expenses Page 1'!A7 -> First name | C5: =+'Expenses Page 1'!C7:F7 -> Zenabu | H5: =+'Expenses Page 1'!H7 -> Valuta (dd.mm.yyyy)
A6: =+'Expenses Page 1'!A8 -> Last name | C6: =+'Expenses Page 1'!C8:F8 -> Suboi
A7: =+'Expenses Page 1'!A11 -> Mission/Purpose | C7: =+'Expenses Page 1'!C11:I11 -> To attend ASTMH 2025 Annual Meeting
A8: =+'Expenses Page 1'!A12 -> Cost centre | C8: =+'Expenses Page 1'!C12 -> 4545 | F8: =+'Expenses Page 1'!F12 -> Currency (for payment) | G8: =+'Expenses Page 1'!G12 -> USD
A11: =+'Expenses Page 1'!A26 -> EXPENSES
A12: =+'Expenses Page 1'!A27 -> No | B12: =+'Expenses Page 1'!B27 -> Date | C12: =+'Expenses Page 1'!C27 -> Disbursement | D12: =+'Expenses Page 1'!D27 -> Acc.code | E12: =+'Expenses Page 1'!E27 -> Budget line | F12: =+'Expenses Page 1'!F27 -> Currency | G12: =+'Expenses Page 1'!G27 -> Amount | H12: =+'Expenses Page 1'!H27 -> Rate | I12: =+'Expenses Page 1'!I27 -> Amount USD | K12: =+'Expenses Page 1'!K27 -> Account
A13: 15 | D13: =IF(ISNA(VLOOKUP(K13,Codes!A$3:B$19,2,FALSE))=TRUE,0,VLOOKUP(K13,Codes!A$3:B$19,2,FALSE)) -> 0 | H13: =IF(F13=$G$8,1,0) -> 0 | I13: =IF(H13<>0,INT(20*(+G13*H13)+0.5)/20,0) -> 0
A14: 16 | D14: =IF(ISNA(VLOOKUP(K14,Codes!A$3:B$19,2,FALSE))=TRUE,0,VLOOKUP(K14,Codes!A$3:B$19,2,FALSE)) -> 0 | H14: =IF(F14=$G$8,1,0) -> 0 | I14: =IF(H14<>0,INT(20*(+G14*H14)+0.5)/20,0) -> 0
A15: 17 | D15: =IF(ISNA(VLOOKUP(K15,Codes!A$3:B$19,2,FALSE))=TRUE,0,VLOOKUP(K15,Codes!A$3:B$19,2,FALSE)) -> 0 | H15: =IF(F15=$G$8,1,0) -> 0 | I15: =IF(H15<>0,INT(20*(+G15*H15)+0.5)/20,0) -> 0
A16: 18 | D16: =IF(ISNA(VLOOKUP(K16,Codes!A$3:B$19,2,FALSE))=TRUE,0,VLOOKUP(K16,Codes!A$3:B$19,2,FALSE)) -> 0 | H16: =IF(F16=$G$8,1,0) -> 0 | I16: =IF(H16<>0,INT(20*(+G16*H16)+0.5)/20,0) -> 0
A17: 19 | D17: =IF(ISNA(VLOOKUP(K17,Codes!A$3:B$19,2,FALSE))=TRUE,0,VLOOKUP(K17,Codes!A$3:B$19,2,FALSE)) -> 0 | H17: =IF(F17=$G$8,1,0) -> 0 | I17: =IF(H17<>0,INT(20*(+G17*H17)+0.5)/20,0) -> 0
A18: 20 | D18: =IF(ISNA(VLOOKUP(K18,Codes!A$3:B$19,2,FALSE))=TRUE,0,VLOOKUP(K18,Codes!A$3:B$19,2,FALSE)) -> 0 | H18: =IF(F18=$G$8,1,0) -> 0 | I18: =IF(H18<>0,INT(20*(+G18*H18)+0.5)/20,0) -> 0
A19: 21 | D19: =IF(ISNA(VLOOKUP(K19,Codes!A$3:B$19,2,FALSE))=TRUE,0,VLOOKUP(K19,Codes!A$3:B$19,2,FALSE)) -> 0 | H19: =IF(F19=$G$8,1,0) -> 0 | I19: =IF(H19<>0,INT(20*(+G19*H19)+0.5)/20,0) -> 0
A20: 22 | D20: =IF(ISNA(VLOOKUP(K20,Codes!A$3:B$19,2,FALSE))=TRUE,0,VLOOKUP(K20,Codes!A$3:B$19,2,FALSE)) -> 0 | H20: =IF(F20=$G$8,1,0) -> 0 | I20: =IF(H20<>0,INT(20*(+G20*H20)+0.5)/20,0) -> 0
A21: 23 | D21: =IF(ISNA(VLOOKUP(K21,Codes!A$3:B$19,2,FALSE))=TRUE,0,VLOOKUP(K21,Codes!A$3:B$19,2,FALSE)) -> 0 | H21: =IF(F21=$G$8,1,0) -> 0 | I21: =IF(H21<>0,INT(20*(+G21*H21)+0.5)/20,0) -> 0
A22: 24 | D22: =IF(ISNA(VLOOKUP(K22,Codes!A$3:B$19,2,FALSE))=TRUE,0,VLOOKUP(K22,Codes!A$3:B$19,2,FALSE)) -> 0 | H22: =IF(F22=$G$8,1,0) -> 0 | I22: =IF(H22<>0,INT(20*(+G22*H22)+0.5)/20,0) -> 0
A23: 25 | D23: =IF(ISNA(VLOOKUP(K23,Codes!A$3:B$19,2,FALSE))=TRUE,0,VLOOKUP(K23,Codes!A$3:B$19,2,FALSE)) -> 0 | H23: =IF(F23=$G$8,1,0) -> 0 | I23: =IF(H23<>0,INT(20*(+G23*H23)+0.5)/20,0) -> 0
A24: 26 | D24: =IF(ISNA(VLOOKUP(K24,Codes!A$3:B$19,2,FALSE))=TRUE,0,VLOOKUP(K24,Codes!A$3:B$19,2,FALSE)) -> 0 | H24: =IF(F24=$G$8,1,0) -> 0 | I24: =IF(H24<>0,INT(20*(+G24*H24)+0.5)/20,0) -> 0
... A47: 49 | D47: =IF(ISNA(VLOOKUP(K47,Codes!A$3:B$19,2,FALSE))=TRUE,0,VLOOKUP(K47,Codes!A$3:B$19,2,FALSE)) -> 0 | H47: =IF(F47=$G$8,1,0) -> 0 | I47: =IF(H47<>0,INT(20*(+G47*H47)+0.5)/20,0) -> 0
A48: =+'Expenses Page 1'!A44 -> Total Expenses Page 2 | I48: =SUM(I13:I47) -> 0

Sheet Example
A1: Please select language / Bitte Sprache wählen | G1: English
A4: =IF($G$1="Deutsch",Codes!$A37,Codes!$B37) -> BILL OF EXPENSES - FIXED ALLOWANCES
A6: =IF($G$1="Deutsch",Codes!$A38,Codes!$B38) -> Documentnr. | C6: This is your reference and it will also appear on the payment received
A7: =IF($G$1="Deutsch",Codes!$A40,Codes!$B40) -> First name | C7: This is mandatory so the payment can be made. For data protection reason, the Bank information for the salary are not available to pay the BoE | H7: =IF($G$1="Deutsch",Codes!$A47,Codes!$B47) -> Valuta (dd.mm.yyyy) | I7: Date when this document is being filled.
A8: =IF($G$1="Deutsch",Codes!$A39,Codes!$B39) -> Last name | H8: =IF($G$1="Deutsch",Codes!$A88,Codes!$B88) -> Finalised by | I8: This is the person who complete
A9: =IF($G$1="Deutsch",Codes!$A41,Codes!$B41) -> Address
A10: =IF($G$1="Deutsch",Codes!$A42,Codes!$B42) -> ZIP/Place
A11: =IF($G$1="Deutsch",Codes!$A43,Codes!$B43) -> Mission/Purpose | C11: Reasons of the expenses or any indications. For EU & SNF Donor this is extremely important information for the financial report.
A12: =IF($G$1="Deutsch",Codes!$A44,Codes!$B44) -> Cost centre | C12: What project is going to cover those expenses, only ONE per BoE | F12: =IF($G$1="Deutsch",Codes!$A48,Codes!$B48) -> Currency (for payment) | G12: CHF
A13: =IF($G$1="Deutsch",Codes!$A45,Codes!$B45) -> From (date) | C13: Mandatory to complete | F13: =IF($G$1="Deutsch",Codes!$A49,Codes!$B49) -> To (date) | G13: Mandatory to complete
A14: =IF($G$1="Deutsch",Codes!$A46,Codes!$B46) -> Place | C14: City where the trip/activity took place, please complete the "Country" in the next cell. | F14: =IF($G$1="Deutsch",Codes!$A50,Codes!$B50) -> Country | G14: Country where the trip/activity took place.
A16: =IF($G$1="Deutsch",Codes!$A51,Codes!$B51) -> FIXED ALLOWANCES | D16: JA | E16: =IF($G$1="Deutsch",Codes!$A52,Codes!$B52) -> Applicable (please select YES or NO)
A17: =IF($G$1="Deutsch",Codes!$A53,Codes!$B53) -> Lump sum per day | D17: if you select yes, indicate the quantity of meal taken out of the office. Please refer to the Manual of Employees for the regulations.
A18: =IF($G$1="Deutsch",Codes!$A54,Codes!$B54) -> Disbursement | B18: =IF($G$1="Deutsch",Codes!$A54,Codes!$B54) -> Disbursement | C18: =IF($G$1="Deutsch",Codes!$A54,Codes!$B54) -> Disbursement | D18: =IF($G$1="Deutsch",Codes!$A54,Codes!$B54) -> Disbursement | E18: =IF($G$1="Deutsch",Codes!$A54,Codes!$B54) -> Disbursement | F18: =IF($G$1="Deutsch",Codes!$A55,Codes!$B55) -> Quantity | G18: =IF($G$1="Deutsch",Codes!$A56,Codes!$B56) -> Budget line | H18: =IF($G$1="Deutsch",Codes!$A57,Codes!$B57) -> Amount | I18: =IF($G$1="Deutsch",Codes!$A58,Codes!$B58) -> Amount CHF
A19: =IF($G$1="Deutsch",Codes!$A59,Codes!$B59) -> Breakfast | B19: =IF($G$1="Deutsch",Codes!$A55,Codes!$B55) -> Quantity | C19: =IF($G$1="Deutsch",Codes!$A62,Codes!$B62) -> If departures is before 7.30 am or respectively with overnight stay (only in case breakfast is not included) | F19: 0 | H19: 10 | I19: =IF(D$16="NO",0,IF(D$16="NEIN",0,+F19*H19)) -> 0
A20: =IF($G$1="Deutsch",Codes!$A60,Codes!$B60) -> Lunch | B20: =IF($G$1="Deutsch",Codes!$A56,Codes!$B56) -> Budget line | F20: 0 | H20: 25 | I20: =IF(D$16="NO",0,IF(D$16="NEIN",0,+F20*H20)) -> 0
A21: =IF($G$1="Deutsch",Codes!$A61,Codes!$B61) -> Dinner | B21: =IF($G$1="Deutsch",Codes!$A57,Codes!$B57) -> Amount | C21: =IF($G$1="Deutsch",Codes!$A63,Codes!$B63) -> In case of external overnight stay or return after 7.30 pm | F21: 0 | H21: 25 | I21: =IF(D$16="NO",0,IF(D$16="NEIN",0,+F21*H21)) -> 0
A22: Private petty expenses for mission abroad - Only when you are not in the country of your contract. | F22: 0 | H22: 5 | I22: =IF(D$16="NO",0,IF(D$16="NEIN",0,+F22*H22)) -> 0
A23: =IF($G$1="Deutsch",Codes!$A65,Codes!$B65) -> TOTAL FIXED ALLOWANCES | I23: =SUM(I19:I22) -> 0
F24: =IF($G$1="Deutsch",Codes!$A66,Codes!$B66) -> Exchange rate (filled in by Accounting) | G24: =IF(G12="CHF",1," ") -> 1 | H24: =+G12 -> CHF | I24: =IF(G12="CHF",I23," ") -> 0
A26: =IF($G$1="Deutsch",Codes!$A67,Codes!$B67) -> EXPENSES
A27: =IF($G$1="Deutsch",Codes!$A68,Codes!$B68) -> No | B27: =IF($G$1="Deutsch",Codes!$A69,Codes!$B69) -> Date | C27: =IF($G$1="Deutsch",Codes!$A70,Codes!$B70) -> Disbursement | D27: =IF($G$1="Deutsch",Codes!$A71,Codes!$B71) -> Acc.code | E27: =IF($G$1="Deutsch",Codes!$A56,Codes!$B56) -> Budget line | F27: =IF($G$1="Deutsch",Codes!$A72,Codes!$B72) -> Currency | G27: =IF($G$1="Deutsch",Codes!$A73,Codes!$B73) -> Amount | H27: =IF($G$1="Deutsch",Codes!$A74,Codes!$B74) -> Rate | I27: =IF($G$1="Deutsch",CONCATENATE(Codes!$A75," ",G$12),CONCATENATE(Codes!$B75," ",G$12)) -> Amount CHF | K27: =IF($G$1="Deutsch",Codes!$A76,Codes!$B76) -> Account
A28: 1 | B28: This is the date on the document | C28: Description of the voucher (one voucher = one line) | D28: For the account, select the accurate one in the column K | E28: Only if available for this project | F28: CHF | G28: 0 | H28: =IF(F28=$H$24,1,0) -> 1 | I28: =IF(H28<>0,INT(20*(+G28*H28)+0.5)/20,0) -> 0
A29: 2 | D29: =IF(ISNA(VLOOKUP(K29,Codes!A$3:B$19,2,FALSE))=TRUE,0,VLOOKUP(K29,Codes!A$3:B$19,2,FALSE)) -> 0 | H29: =IF(F29=$H$24,1,0) -> 0 | I29: =IF(H29<>0,INT(20*(+G29*H29)+0.5)/20,0) -> 0
A30: 3 | D30: =IF(ISNA(VLOOKUP(K30,Codes!A$3:B$19,2,FALSE))=TRUE,0,VLOOKUP(K30,Codes!A$3:B$19,2,FALSE)) -> 0 | H30: =IF(F30=$H$24,1,0) -> 0 | I30: =IF(H30<>0,INT(20*(+G30*H30)+0.5)/20,0) -> 0
A31: 4 | D31: =IF(ISNA(VLOOKUP(K31,Codes!A$3:B$19,2,FALSE))=TRUE,0,VLOOKUP(K31,Codes!A$3:B$19,2,FALSE)) -> 0 | H31: =IF(F31=$H$24,1,0) -> 0 | I31: =IF(H31<>0,INT(20*(+G31*H31)+0.5)/20,0) -> 0
A32: 5 | D32: =IF(ISNA(VLOOKUP(K32,Codes!A$3:B$19,2,FALSE))=TRUE,0,VLOOKUP(K32,Codes!A$3:B$19,2,FALSE)) -> 0 | H32: =IF(F32=$H$24,1,0) -> 0 | I32: =IF(H32<>0,INT(20*(+G32*H32)+0.5)/20,0) -> 0
A33: 6 | D33: =IF(ISNA(VLOOKUP(K33,Codes!A$3:B$19,2,FALSE))=TRUE,0,VLOOKUP(K33,Codes!A$3:B$19,2,FALSE)) -> 0 | H33: =IF(F33=$H$24,1,0) -> 0 | I33: =IF(H33<>0,INT(20*(+G33*H33)+0.5)/20,0) -> 0
A34: 7 | D34: =IF(ISNA(VLOOKUP(K34,Codes!A$3:B$19,2,FALSE))=TRUE,0,VLOOKUP(K34,Codes!A$3:B$19,2,FALSE)) -> 0 | H34: =IF(F34=$H$24,1,0) -> 0 | I34: =IF(H34<>0,INT(20*(+G34*H34)+0.5)/20,0) -> 0
A35: 8 | D35: =IF(ISNA(VLOOKUP(K35,Codes!A$3:B$19,2,FALSE))=TRUE,0,VLOOKUP(K35,Codes!A$3:B$19,2,FALSE)) -> 0 | H35: =IF(F35=$H$24,1,0) -> 0 | I35: =IF(H35<>0,INT(20*(+G35*H35)+0.5)/20,0) -> 0
A36: 9 | D36: =IF(ISNA(VLOOKUP(K36,Codes!A$3:B$19,2,FALSE))=TRUE,0,VLOOKUP(K36,Codes!A$3:B$19,2,FALSE)) -> 0 | H36: =IF(F36=$H$24,1,0) -> 0 | I36: =IF(H36<>0,INT(20*(+G36*H36)+0.5)/20,0) -> 0
A37: 10 | D37: =IF(ISNA(VLOOKUP(K37,Codes!A$3:B$19,2,FALSE))=TRUE,0,VLOOKUP(K37,Codes!A$3:B$19,2,FALSE)) -> 0 | H37: =IF(F37=$H$24,1,0) -> 0 | I37: =IF(H37<>0,INT(20*(+G37*H37)+0.5)/20,0) -> 0
A38: 11 | D38: =IF(ISNA(VLOOKUP(K38,Codes!A$3:B$19,2,FALSE))=TRUE,0,VLOOKUP(K38,Codes!A$3:B$19,2,FALSE)) -> 0 | H38: =IF(F38=$H$24,1,0) -> 0 | I38: =IF(H38<>0,INT(20*(+G38*H38)+0.5)/20,0) -> 0
A39: 12 | D39: =IF(ISNA(VLOOKUP(K39,Codes!A$3:B$19,2,FALSE))=TRUE,0,VLOOKUP(K39,Codes!A$3:B$19,2,FALSE)) -> 0 | H39: =IF(F39=$H$24,1,0) -> 0 | I39: =IF(H39<>0,INT(20*(+G39*H39)+0.5)/20,0) -> 0
A40: 13 | D40: =IF(ISNA(VLOOKUP(K40,Codes!A$3:B$19,2,FALSE))=TRUE,0,VLOOKUP(K40,Codes!A$3:B$19,2,FALSE)) -> 0 | H40: =IF(F40=$H$24,1,0) -> 0 | I40: =IF(H40<>0,INT(20*(+G40*H40)+0.5)/20,0) -> 0
A41: 14 | D41: =IF(ISNA(VLOOKUP(K41,Codes!A$3:B$19,2,FALSE))=TRUE,0,VLOOKUP(K41,Codes!A$3:B$19,2,FALSE)) -> 0 | H41: =IF(F41=$H$24,1,0) -> 0 | I41: =IF(H41<>0,INT(20*(+G41*H41)+0.5)/20,0) -> 0
A43: =IF($G$1="Deutsch",Codes!$A77,Codes!$B77) -> Total Expenses Page 1 | I43: =SUM(I28:I41) -> 0
A44: =IF($G$1="Deutsch",Codes!$A78,Codes!$B78) -> Total Expenses Page 2 | D44: Complete Page 2 if there is not enough place, it will automatically be reported on the first page. | I44: =+'Expenses Page 2'!I48 -> 0
A45: =IF($G$1="Deutsch",Codes!$A79,Codes!$B79) -> TOTAL EXPENSES | I45: =SUM(I43:I44) -> 0
A46: =IF($G$1="Deutsch",Codes!$A65,Codes!$B65) -> TOTAL FIXED ALLOWANCES | I46: =IF(G12<>"CHF"," ",+I23) -> 0
...

Sheet Codes
A2: Description | B2: Account Code
A3: 422000 Travel costs | B3: 422000
A4: 422010 Accommodation and boarding costs | B4: 422010
A5: 423000 Medical examinations, vaccinations etc. | B5: 423000
A6: 423020 Other personnel costs | B6: 423020
A7: 421000 Continuous education | B7: 421000
A8: 500000 Procurement of material | B8: 500000
A9: 500040 Books | B9: 500040
A10: 510010 Procurement equipment < CHF 5'000 | B10: 510010
A11: 550000 Office material, printed matters | B11: 550000
A12: 550010 Photocopies | B12: 550010
A13: 550020 Telephone, Fax, Internet | B13: 550020
A14: 550030 Postage | B14: 550030
... A18: 568000 Field expenses (Remuneration field workers, consumables bought + used locally) | B18: 568000
A19: Other expenses | B19: Other
A22: Currencies
A23: CHF
A24: USD
A25: EUR
A26: GBP
A28: Applicable | B28: Applicable
A29: JA | B29: YES
A30: NEIN | B30: NO
A32: Sprache
A33: Deutsch
A34: English
A36: DE | B36: EN
A37: SPESENABRECHNUNG - PAUSCHALVERGÜTUNGEN | B37: BILL OF EXPENSES - FIXED ALLOWANCES
A38: Dokumenten-Nr. | B38: Documentnr.
A39: Nachname | B39: Last name
A40: Vorname | B40: First name
A41: Adresse | B41: Address
A42: PLZ/Ort | B42: ZIP/Place
A43: Mission/Zweck | B43: Mission/Purpose
A44: Kostenstelle | B44: Cost centre
A45: Von (Datum) | B45: From (date)
A46: Ort | B46: Place
A47: Valuta (tt.mm.jjjj) | B47: Valuta (dd.mm.yyyy)
... A74: Kurs | B74: Rate
A75: =CONCATENATE("Betrag"," ",G$19) -> Betrag | B75: =CONCATENATE("Amount"," ",G$19) -> Amount
...
